Workbook
Name _Hlk22646034: 'Budget détaillé'!#REF!

Sheet Budget détaillé
A3: Génération Sans Limites/ Youth Challenge 2019/2020
A4: BUDGET ESTIMATIF Youth Challenge Congo
A5: N⁰ | B5: Description du poste | C5: Nombre d’unités | D5: Types d’Unités | E5: Fréquence | F5: Unité de Fréquence | G5: Prix/coût unitaire | H5: Montant total | I5: Montant en USD | J5: Source de financement
I6: 590.42 | J6: GenU | K6: UNDP | L6: UNICEF
A7: Extrant 1 | B7: Sensibilisation sur le projet "Youth Challenge"
A8: Activité 1.1 | B8: Communication sur le projet (dépliants, gadgets, presse, etc.)
A9: Grp.Cibles | B9: Grand public: Décideurs, ministres, partenaires techniques et financiers…
B10: Confection des banderoles en bâche | C10: 4 | D10: Unité | E10: 1 | F10: fois | G10: 40000 | H10: =G10*E10*C10 -> 160000
B11: Déploiement banderoles (achat corde et per diem pour les manutentionnaires) | C11: 4 | D11: Unité | E11: 1 | F11: fois | G11: 2000 | H11: =G11*E11*C11 -> 8000
B12: Conception des Kakemono | C12: 2 | D12: Unité | E12: 1 | F12: fois | G12: 150000 | H12: =G12*E12*C12 -> 300000
B13: Conception des supports visuels: Affiches Dépliants | C13: 2 | D13: Produits | E13: 1 | F13: fois | G13: 100000 | H13: =G13*E13*C13 -> 200000
B14: Impression Affiches A3 | C14: 100 | D14: Exemplaires | E14: 1 | F14: tirage | G14: 1500 | H14: =G14*E14*C14 -> 150000
B15: Impression dépliants A4 | C15: 300 | D15: Exemplaires | E15: 1 | F15: Tirage | G15: 1000 | H15: =G15*E15*C15 -> 300000
B16: Diffusion d'un communiqué radio/ télévisé | C16: 1 | D16: Communiqué | E16: 5 | F16: Diffusions | G16: 20000 | H16: =G16*E16*C16 -> 100000
B17: Réseaux sociaux | C17: 1 | D17: Publication | E17: 1 | F17: Année | G17: 10000 | H17: =G17*E17*C17 -> 10000
B18: Décoration T-shirts | C18: 100 | D18: t-shirts | E18: 2 | F18: tirage | G18: 3000 | H18: =G18*E18*C18 -> 600000
B19: Décoration Polos | C19: 55 | D19: Polos | E19: 1 | F19: Impression | G19: 5000 | H19: =G19*E19*C19 -> 275000
B20: Organisation des réunions de sensibilisation | C20: 5 | D20: Réunions | E20: 1 | F20: Forfait | G20: 50000 | H20: =G20*E20*C20 -> 250000
A21: Sous-total activité 1.1: Communication sur le projet (dépliants, gadgets, presse, etc.) | H21: =SUM(H10:H20) -> 2353000 | I21: =H21/I6 -> 3985.2986 | J21: 1000 | K21: 0 | L21: =I21-J21-K21 -> 2985.2986
A22: Activité 1.2. | B22: Organisation de la cérémonie de lancement du Youth Challenge
A23: Grp.Cibles | B23: Ministères, Secteur privé,SNU, Médias , potentiels candidats
B24: Location de la salle | C24: 1 | E24: 1 | F24: Jour | G24: 150000 | H24: =C24*E24*G24 -> 150000
B25: Cocktail participants | C25: 150 | D25: Personnes | E25: 1 | F25: Jour | G25: 10000 | H25: =C25*E25*G25 -> 1500000
B26: Couverture médiatique (transport des journaliste) | C26: 20 | D26: Journalistes | E26: 1 | F26: jour | G26: 5000 | H26: =C26*E26*G26 -> 100000
B27: Reportage photo-vidéo | C27: 2 | D27: reporter | E27: 1 | F27: jour | G27: 150000 | H27: =C27*E27*G27 -> 300000
A28: Sous-total 1.2. | B28: Organisation de la cérémonie de lancement du Youth Challenge | H28: =SUM(H24:H27) -> 2050000 | I28: =H28/I6 -> 3472.1046 | J28: 0 | K28: 0 | L28: =I28-J28-K28 -> 3472.1046
A29: TOTAL DE L’EXTRANT 1: Sensibilisation sur le projet | H29: =H21+H28 -> 4403000 | I29: =I21+I28 -> 7457.4032 | J29: =J21+J28 -> 1000 | K29: 0 | L29: =L21+L28 -> 6457.4032
A30: Extrant 2 | B30: Organisation des ateliers de conception ( Boootcamps)
A31: Activité 2.1 | B31: Préparation des ateliers
A32: Grp.Cibles | B32: Ministères, partenaires techniques et financiers éventuels participants
B33: Collation pendant le briefing du comite de présélection | C33: 10 | D33: Personne | E33: 1 | F33: réunion | G33: 3000 | H33: =C33*E33*G33 -> 30000
B34: collation pendant les réunions du comité de pre-selection sélection des offres | C34: 10 | D34: Personnes | E34: 2 | F34: Réunions | G34: 2000 | H34: =C34*E34*G34 -> 40000
B35: Constitution des kits pour les membres du comité ( feuilles, stylos, de notation, blocs notes etc.) | C35: 10 | D35: Personnes | E35: 1 | F35: Kit | G35: 1500 | H35: =C35*E35*G35 -> 15000
B36: Frais de transport pour les membres du comité de sélection | C36: 5 | D36: Personnes | E36: 2 | F36: réunion | G36: 5000 | H36: =C36*E36*G36 -> 50000
B37: Duplication des fiches d'inscription | C37: 1 | D37: fiche de 2 pages | E37: 200 | F37: copies | G37: 50 | H37: =C37*E37*G37 -> 10000
A38: Sous-total 2.1 | B38: Préparation des ateliers | H38: =SUM(H33:H37) -> 145000 | I38: =H38/I6 -> 245.58789 | J38: 0 | K38: =I38 -> 245.58789 | L38: =I38-J38-K38 -> 0
A39: Activité 2.2 | B39: organisation de l'atelier d'orientation
A40: Grp.Cibles | B40: candidats, coach, équipes, superviseurs, comite technique
B41: Kits de formation | C41: 50 | D41: personnes | E41: 1 | F41: Jour | G41: 2000 | H41: =G41*E41*C41 -> 100000
B42: collation pendant l'atelier d'orientation | C42: 60 | D42: Personnes | E42: 1 | F42: Jour | G42: 3000 | H42: =G42*E42*C42 -> 180000
...

Sheet Apport par structure
A4: Génération Sans Limites/ Youth Challenge 2019/2020
A5: Contributions des différentes parties prenantes par activité
A7: 1- Financement de Generation Unlimeted
A8: Activités | B8: Montant en USD
A9: Communication sur le projet (dépliants, gadgets, presse, etc.) | B9: ='Budget détaillé'!J21 -> 1000
A10: Organisation des ateliers résidentiels de conception( Bootcam) | B10: ='Budget détaillé'!J50 -> 9000
A11: Remise des prix aux gagnants | B11: ='Budget détaillé'!J56 -> 5000
A13: Total Financement GenU | B13: =B9+B10+B11 -> 15000
A15: 2- Apport UNDP
A16: Activités | B16: Montant en USD
A17: Préparation des ateliers | B17: ='Budget détaillé'!I38 -> 245.58789
A18: Organisation de l'atelier d'orientation | B18: ='Budget détaillé'!K46 -> 1194.0652
A19: Complément organisation des ateliers résidentiels de conception (Bootcam) | B19: ='Budget détaillé'!K50 -> 5904.6442
A20: Organisation de la cérémonie de publication des résultats | B20: ='Budget détaillé'!K62 -> 847
A21: Total Apport UNDP | B21: =SUM(B17:B20) -> 8191.2973
A23: 2- Apport UNICEF
A24: Activités | B24: Montant en USD
A25: Communication sur le projet (dépliants, gadgets, presse, etc.) | B25: ='Budget détaillé'!L21 -> 2985.2986
A26: Organisation de la cérémonie de lancement du Youth Challenge | B26: ='Budget détaillé'!L28 -> 3472.1046
A27: Accompagnement des projets | B27: ='Budget détaillé'!L68 -> 1625.9612
A28: Total Apport UNICEF | B28: =SUM(B25:B27) -> 8083.3644
